Workbook

Sheet Start Here
A1: XPMatch — Financial Model
A2: Pre-launch prospectus companion · Last updated Sunday, Sep 21, 2026
A4: FOUNDER INPUTS ARE DEFAULTS
A5: Nine founder-side inputs were not supplied and have been defaulted: ownership and equity split, founder hours,
A6: entity, capital available, spend to date, owner compensation, revenue to date, other businesses, and non-competes.
A7: All nine are tagged [A]. Replace them before this workbook is shown to a lender or a partner.
A9: HOW TO USE THIS WORKBOOK
A10: 1. Assumptions — every input lives here. Blue cells are yours to change.
A11: 2. Scenario levers (yellow, bottom of Assumptions) — set 0.70 to model a 30% miss, 1.30 for 30% better.
A12: 3. Key Metrics — the Financial Quickview. Recomputes the moment a lever moves.
A13: 4. Monthly Model — the 36-month engine. Volume inputs (blue) at the top, everything else is formula.
A14: 5. Year 1 Monthly · Annual Views · SDE Add-backs — presentation views, all linked.
... A31: Counts across the model: 1 Verified · 17 Estimated · 20 Assumed. Verified share: 3%.

Sheet Key Metrics
A1: Financial Quickview
A2: Every figure is computed live. Change a scenario lever on Assumptions and this page moves.
A4: Metric | B4: Value | C4: Tag
A5: Startup capital required (business) | B5: =Assumptions!$B$47+MAX(0,Assumptions!$B$46-MIN('Monthly Model'!$B$66:$AK$66))+3*'Monthly Model'!$M$60 -> 12095.013 | C5: E
A6: of which: one-time build costs | B6: =Assumptions!$B$47 -> 3850 | C6: A
A7: of which: month-1 cash drawdown | B7: =MAX(0,Assumptions!$B$46-MIN('Monthly Model'!$B$66:$AK$66)) -> 3670.0133 | C7: E
A8: of which: working-capital buffer (3 × M12 opex) | B8: =3*'Monthly Model'!$M$60 -> 4575 | C8: E
A9: Founder personal runway (12 mo unpaid) | B9: 48000 | C9: A
A10: Total cash founders must hold | B10: =B5+B9 -> 60095.013 | C10: A
A11: Founder cash available | B11: =Assumptions!$B$46 -> 25000 | C11: A
A12: Shortfall | B12: =B11-B10 -> -35095.013 | C12: A
A14: Months to first revenue | B14: =COUNTIF('Monthly Model'!$B$42:$AK$42,"<=0")+1 -> 1 | C14: E
A15: Months to cash breakeven | B15: =COUNTIF('Monthly Model'!$B$65:$AK$65,"<=0")+1 -> 2 | C15: E
A17: Year-1 revenue | B17: ='Annual Views'!B5 -> 40122.525 | C17: A
A18: Year-3 revenue | B18: ='Annual Views'!D5 -> 427320.02 | C18: A
A19: Year-3 SDE | B19: ='SDE Add-backs'!D13 -> 197357.01 | C19: A
A20: Year-3 SDE margin | B20: =IF('Annual Views'!D5=0,0,'SDE Add-backs'!D13/'Annual Views'!D5) -> 0.46184828 | C20: A
A21: Year-3 exit ARR run-rate | B21: ='Monthly Model'!$AK$42*12 -> 548932.39 | C21: A
A23: Target exit multiple (SDE) | B23: =Assumptions!$B$49 -> 3.2 | C23: E
A24: Implied Year-3 valuation | B24: =B19*B23 -> 631542.44 | C24: derived
A25: Founder hours / week (launch → steady) | B25: 50 → 30 | C25: A
A26: Financing path | B26: Bootstrapped, revenue-first | C26: —
A28: Scenario levers (live — edit on Assumptions)
A29: Advisor seat adds multiplier | B29: =Assumptions!$B$63 -> 1
A30: Free-to-paid conversion multiplier | B30: =Assumptions!$B$64 -> 1
A31: Signup volume multiplier | B31: =Assumptions!$B$65 -> 1
A32: COGS multiplier | B32: =Assumptions!$B$66 -> 1
A33: Concierge volume multiplier | B33: =Assumptions!$B$67 -> 1
A34: Affiliate per-trip multiplier | B34: =Assumptions!$B$68 -> 1
A35: Cities seeded multiplier | B35: =Assumptions!$B$69 -> 1

Sheet Annual Views
A1: Three-Year Projection
A2: Year 1 = months 1–12, Year 2 = 13–24, Year 3 = 25–36. Every cell sums the Monthly Model.
B4: Year 1 | C4: Year 2 | D4: Year 3
A5: Revenue | B5: =SUM('Monthly Model'!$B$42:$M$42) -> 40122.525 | C5: =SUM('Monthly Model'!$N$42:$Y$42) -> 190673.03 | D5: =SUM('Monthly Model'!$Z$42:$AK$42) -> 427320.02
A6: Growth YoY | B6: ="" | C6: =C5/B5-1 -> 3.7522689 | D6: =D5/C5-1 -> 1.2411141
A7: Cost of goods sold | B7: =SUM('Monthly Model'!$B$49:$M$49) -> 7688.3695 | C7: =SUM('Monthly Model'!$N$49:$Y$49) -> 48920.474 | D7: =SUM('Monthly Model'!$Z$49:$AK$49) -> 106163
A8: Gross profit | B8: =SUM('Monthly Model'!$B$50:$M$50) -> 32434.155 | C8: =SUM('Monthly Model'!$N$50:$Y$50) -> 141752.55 | D8: =SUM('Monthly Model'!$Z$50:$AK$50) -> 321157.01
A9: Gross margin | B9: =IF(B5=0,0,B8/B5) -> 0.80837772 | C9: =IF(C5=0,0,C8/C5) -> 0.74343264 | D9: =IF(D5=0,0,D8/D5) -> 0.75156089
A10: Advertising & marketing | B10: =SUM('Monthly Model'!$B$54:$M$54) -> 7200 | C10: =SUM('Monthly Model'!$N$54:$Y$54) -> 24000 | D10: =SUM('Monthly Model'!$Z$54:$AK$54) -> 48000
A11: Contractors & staff | B11: =SUM('Monthly Model'!$B$55:$M$55) -> 0 | C11: =SUM('Monthly Model'!$N$55:$Y$55) -> 15000 | D11: =SUM('Monthly Model'!$Z$55:$AK$55) -> 36000
A12: Software, hosting & sending | B12: =SUM('Monthly Model'!$B$56:$M$56)+SUM('Monthly Model'!$B$57:$M$57)+SUM('Monthly Model'!$B$58:$M$58) -> 3900 | C12: =SUM('Monthly Model'!$N$56:$Y$56)+SUM('Monthly Model'!$N$57:$Y$57)+SUM('Monthly Model'!$N$58:$Y$58) -> 8400 | D12: =SUM('Monthly Model'!$Z$56:$AK$56)+SUM('Monthly Model'!$Z$57:$AK$57)+SUM('Monthly Model'!$Z$58:$AK$58) -> 13800
A13: Owner salary | B13: =SUM('Monthly Model'!$B$59:$M$59) -> 0 | C13: =SUM('Monthly Model'!$N$59:$Y$59) -> 48000 | D13: =SUM('Monthly Model'!$Z$59:$AK$59) -> 96000
A14: Total operating expenses | B14: =SUM('Monthly Model'!$B$60:$M$60) -> 11100 | C14: =SUM('Monthly Model'!$N$60:$Y$60) -> 95400 | D14: =SUM('Monthly Model'!$Z$60:$AK$60) -> 193800
A15: Net operating profit | B15: =SUM('Monthly Model'!$B$61:$M$61) -> 21334.155 | C15: =SUM('Monthly Model'!$N$61:$Y$61) -> 46352.552 | D15: =SUM('Monthly Model'!$Z$61:$AK$61) -> 127357.01
A16: One-time costs | B16: =SUM('Monthly Model'!$B$64:$M$64) -> 3850 | C16: =SUM('Monthly Model'!$N$64:$Y$64) -> 0 | D16: =SUM('Monthly Model'!$Z$64:$AK$64) -> 0
A17: Exit-month ARR run-rate | B17: ='Monthly Model'!$M$42*12 -> 80379.461 | C17: ='Monthly Model'!$Y$42*12 -> 275874.69 | D17: ='Monthly Model'!$AK$42*12 -> 548932.39
A18: Paying accounts at year end | B18: ='Monthly Model'!$M$32 -> 171.25034 | C18: ='Monthly Model'!$Y$32 -> 853.30779 | D18: ='Monthly Model'!$AK$32 -> 2100.1296
A19: Advisor seats at year end | B19: ='Monthly Model'!$M$30 -> 49.070917 | C19: ='Monthly Model'!$Y$30 -> 174.58798 | D19: ='Monthly Model'!$AK$30 -> 405.47699

Sheet Year 1 Monthly
A1: Year 1 — Monthly Detail (Oct 2026 – Sep 2027)
A2: Green = linked from Monthly Model. Edit inputs there, not here.
B3: M1 | C3: M2 | D3: M3 | E3: M4 | F3: M5 | G3: M6 | H3: M7 | I3: M8 | J3: M9 | K3: M10 | L3: M11 | M3: M12 | N3: Year 1
A4: New signups | B4: ='Monthly Model'!B13 -> 100 | C4: ='Monthly Model'!C13 -> 150 | D4: ='Monthly Model'!D13 -> 220 | E4: ='Monthly Model'!E13 -> 300 | F4: ='Monthly Model'!F13 -> 400 | G4: ='Monthly Model'!G13 -> 500 | H4: ='Monthly Model'!H13 -> 650 | I4: ='Monthly Model'!I13 -> 800 | ... M4: ='Monthly Model'!M13 -> 1500 | N4: =SUM(B4:M4) -> 7970
A5: Plus subs — annual | B5: ='Monthly Model'!B28 -> 0.9 | C5: ='Monthly Model'!C28 -> 2.25 | D5: ='Monthly Model'!D28 -> 4.23 | E5: ='Monthly Model'!E28 -> 6.93 | F5: ='Monthly Model'!F28 -> 10.53 | G5: ='Monthly Model'!G28 -> 15.03 | H5: ='Monthly Model'!H28 -> 20.88 | I5: ='Monthly Model'!I28 -> 28.08 | ... M5: ='Monthly Model'!M28 -> 71.73 | N5: =M5 -> 71.73
A6: Plus subs — monthly | B6: ='Monthly Model'!B29 -> 0.9 | C6: ='Monthly Model'!C29 -> 2.142 | D6: ='Monthly Model'!D29 -> 3.86496 | E6: ='Monthly Model'!E29 -> 6.1011648 | F6: ='Monthly Model'!F29 -> 8.969025 | G6: ='Monthly Model'!G29 -> 12.392742 | H6: ='Monthly Model'!H29 -> 16.755613 | I6: ='Monthly Model'!I29 -> 21.944939 | ... M6: ='Monthly Model'!M29 -> 50.449424 | N6: =M6 -> 50.449424
A7: Advisor seats | B7: ='Monthly Model'!B30 -> 0 | C7: ='Monthly Model'!C30 -> 0 | D7: ='Monthly Model'!D30 -> 2 | E7: ='Monthly Model'!E30 -> 4.9 | F7: ='Monthly Model'!F30 -> 8.655 | G7: ='Monthly Model'!G30 -> 13.22225 | H7: ='Monthly Model'!H30 -> 18.561138 | I7: ='Monthly Model'!I30 -> 23.633081 | ... M7: ='Monthly Model'!M30 -> 49.070917 | N7: =M7 -> 49.070917
A8: Concierge trips | B8: ='Monthly Model'!B15 -> 2 | C8: ='Monthly Model'!C15 -> 3 | D8: ='Monthly Model'!D15 -> 4 | E8: ='Monthly Model'!E15 -> 5 | F8: ='Monthly Model'!F15 -> 6 | G8: ='Monthly Model'!G15 -> 7 | H8: ='Monthly Model'!H15 -> 8 | I8: ='Monthly Model'!I15 -> 8 | ... M8: ='Monthly Model'!M15 -> 10 | N8: =SUM(B8:M8) -> 82
A10: Plus — annual | B10: ='Monthly Model'!B36 -> 3.675 | C10: ='Monthly Model'!C36 -> 9.1875 | D10: ='Monthly Model'!D36 -> 17.2725 | E10: ='Monthly Model'!E36 -> 28.2975 | F10: ='Monthly Model'!F36 -> 42.9975 | G10: ='Monthly Model'!G36 -> 61.3725 | H10: ='Monthly Model'!H36 -> 85.26 | I10: ='Monthly Model'!I36 -> 114.66 | ... M10: ='Monthly Model'!M36 -> 292.8975 | N10: =SUM(B10:M10) -> 1232.9625
A11: Plus — monthly | B11: ='Monthly Model'!B37 -> 7.191 | C11: ='Monthly Model'!C37 -> 17.11458 | D11: ='Monthly Model'!D37 -> 30.88103 | E11: ='Monthly Model'!E37 -> 48.748307 | F11: ='Monthly Model'!F37 -> 71.66251 | G11: ='Monthly Model'!G37 -> 99.018009 | H11: ='Monthly Model'!H37 -> 133.87735 | I11: ='Monthly Model'!I37 -> 175.34007 | ... M11: ='Monthly Model'!M37 -> 403.0909 | N11: =SUM(B11:M11) -> 1820.0226
A12: Trip Pass | B12: ='Monthly Model'!B38 -> 41.8 | C12: ='Monthly Model'!C38 -> 62.7 | D12: ='Monthly Model'!D38 -> 91.96 | E12: ='Monthly Model'!E38 -> 125.4 | F12: ='Monthly Model'!F38 -> 167.2 | G12: ='Monthly Model'!G38 -> 209 | H12: ='Monthly Model'!H38 -> 271.7 | I12: ='Monthly Model'!I38 -> 334.4 | ... M12: ='Monthly Model'!M38 -> 627 | N12: =SUM(B12:M12) -> 3331.46
A13: Advisor seats | B13: ='Monthly Model'!B39 -> 0 | C13: ='Monthly Model'!C39 -> 0 | D13: ='Monthly Model'!D39 -> 98 | E13: ='Monthly Model'!E39 -> 240.1 | F13: ='Monthly Model'!F39 -> 424.095 | G13: ='Monthly Model'!G39 -> 647.89025 | H13: ='Monthly Model'!H39 -> 909.49574 | I13: ='Monthly Model'!I39 -> 1158.021 | ... M13: ='Monthly Model'!M39 -> 2404.4749 | N13: =SUM(B13:M13) -> 11154.976
A14: Concierge | B14: ='Monthly Model'!B40 -> 498 | C14: ='Monthly Model'!C40 -> 747 | D14: ='Monthly Model'!D40 -> 996 | E14: ='Monthly Model'!E40 -> 1245 | F14: ='Monthly Model'!F40 -> 1494 | G14: ='Monthly Model'!G40 -> 1743 | H14: ='Monthly Model'!H40 -> 1992 | I14: ='Monthly Model'!I40 -> 1992 | ... M14: ='Monthly Model'!M40 -> 2490 | N14: =SUM(B14:M14) -> 20418
A15: Affiliate | B15: ='Monthly Model'!B41 -> 0 | C15: ='Monthly Model'!C41 -> 0 | D15: ='Monthly Model'!D41 -> 0 | E15: ='Monthly Model'!E41 -> 0 | F15: ='Monthly Model'!F41 -> 0 | G15: ='Monthly Model'!G41 -> 157.3161 | H15: ='Monthly Model'!H41 -> 205.11542 | I15: ='Monthly Model'!I41 -> 253.25844 | ... M15: ='Monthly Model'!M41 -> 480.82506 | N15: =SUM(B15:M15) -> 2165.1032
A16: Total revenue | B16: ='Monthly Model'!B42 -> 550.666 | C16: ='Monthly Model'!C42 -> 836.00208 | D16: ='Monthly Model'!D42 -> 1234.1135 | E16: ='Monthly Model'!E42 -> 1687.5458 | F16: ='Monthly Model'!F42 -> 2199.955 | G16: ='Monthly Model'!G42 -> 2917.5969 | H16: ='Monthly Model'!H42 -> 3597.4485 | I16: ='Monthly Model'!I42 -> 4027.6795 | ... M16: ='Monthly Model'!M42 -> 6698.2884 | N16: =SUM(B16:M16) -> 40122.525
A18: Total COGS | B18: ='Monthly Model'!B49 -> 86.104303 | C18: ='Monthly Model'!C49 -> 161.39078 | D18: ='Monthly Model'!D49 -> 247.30327 | E18: ='Monthly Model'!E49 -> 340.07473 | F18: ='Monthly Model'!F49 -> 440.56959 | G18: ='Monthly Model'!G49 -> 551.13021 | H18: ='Monthly Model'!H49 -> 668.92974 | I18: ='Monthly Model'!I49 -> 778.74875 | ... M18: ='Monthly Model'!M49 -> 1301.1754 | N18: =SUM(B18:M18) -> 7688.3695
A19: Gross profit | B19: ='Monthly Model'!B50 -> 464.5617 | C19: ='Monthly Model'!C50 -> 674.6113 | D19: ='Monthly Model'!D50 -> 986.81026 | E19: ='Monthly Model'!E50 -> 1347.4711 | F19: ='Monthly Model'!F50 -> 1759.3854 | G19: ='Monthly Model'!G50 -> 2366.4666 | H19: ='Monthly Model'!H50 -> 2928.5188 | I19: ='Monthly Model'!I50 -> 3248.9307 | ... M19: ='Monthly Model'!M50 -> 5397.113 | N19: =SUM(B19:M19) -> 32434.155
A20: Gross margin | B20: ='Monthly Model'!B51 -> 0.84363606 | C20: ='Monthly Model'!C51 -> 0.80694931 | D20: ='Monthly Model'!D51 -> 0.7996106 | E20: ='Monthly Model'!E51 -> 0.79847971 | F20: ='Monthly Model'!F51 -> 0.799737 | G20: ='Monthly Model'!G51 -> 0.81110131 | H20: ='Monthly Model'!H51 -> 0.81405439 | I20: ='Monthly Model'!I51 -> 0.80665076 | ... M20: ='Monthly Model'!M51 -> 0.80574509 | N20: =IF(N18=0,0,N19/N18) -> 4.2185999
A22: Total operating expenses | B22: ='Monthly Model'!B60 -> 325 | C22: ='Monthly Model'!C60 -> 325 | D22: ='Monthly Model'!D60 -> 325 | E22: ='Monthly Model'!E60 -> 725 | F22: ='Monthly Model'!F60 -> 825 | G22: ='Monthly Model'!G60 -> 925 | H22: ='Monthly Model'!H60 -> 1025 | I22: ='Monthly Model'!I60 -> 1125 | ... M22: ='Monthly Model'!M60 -> 1525 | N22: =SUM(B22:M22) -> 11100
A23: Net operating profit | B23: ='Monthly Model'!B61 -> 139.5617 | C23: ='Monthly Model'!C61 -> 349.6113 | D23: ='Monthly Model'!D61 -> 661.81026 | E23: ='Monthly Model'!E61 -> 622.47108 | F23: ='Monthly Model'!F61 -> 934.38542 | G23: ='Monthly Model'!G61 -> 1441.4666 | H23: ='Monthly Model'!H61 -> 1903.5188 | I23: ='Monthly Model'!I61 -> 2123.9307 | ... M23: ='Monthly Model'!M61 -> 3872.113 | N23: =SUM(B23:M23) -> 21334.155
A24: One-time costs | B24: ='Monthly Model'!B64 -> 3850 | C24: ='Monthly Model'!C64 -> 0 | D24: ='Monthly Model'!D64 -> 0 | E24: ='Monthly Model'!E64 -> 0 | F24: ='Monthly Model'!F64 -> 0 | G24: ='Monthly Model'!G64 -> 0 | H24: ='Monthly Model'!H64 -> 0 | I24: ='Monthly Model'!I64 -> 0 | ... M24: ='Monthly Model'!M64 -> 0 | N24: =SUM(B24:M24) -> 3850
A25: Net cash flow | B25: ='Monthly Model'!B65 -> -3670.0133 | C25: ='Monthly Model'!C65 -> 406.5738 | D25: ='Monthly Model'!D65 -> 741.55776 | E25: ='Monthly Model'!E65 -> 726.47358 | F25: ='Monthly Model'!F65 -> 1067.7879 | G25: ='Monthly Model'!G65 -> 1600.5941 | H25: ='Monthly Model'!H65 -> 2104.9088 | I25: ='Monthly Model'!I65 -> 2362.0707 | ... M25: ='Monthly Model'!M65 -> 4240.7155 | N25: =SUM(B25:M25) -> 19765.963
A26: Cumulative cash | B26: ='Monthly Model'!B66 -> 21329.987 | C26: ='Monthly Model'!C66 -> 21736.561 | D26: ='Monthly Model'!D66 -> 22478.118 | E26: ='Monthly Model'!E66 -> 23204.592 | F26: ='Monthly Model'!F66 -> 24272.38 | G26: ='Monthly Model'!G66 -> 25872.974 | H26: ='Monthly Model'!H66 -> 27977.883 | I26: ='Monthly Model'!I66 -> 30339.953 | ... M26: ='Monthly Model'!M66 -> 44765.963 | N26: =M26 -> 44765.963

Sheet SDE Add-backs
A1: SDE Add-backs — Detail
A2: SDE assumes ONE owner-operator. Owner salary is added back. The SECOND founder's unpaid hours are SUBTRACTED, because a buyer must pay someone for them — as is founder concierge review before the reviewer is hired.
B4: Year 1 | C4: Year 2 | D4: Year 3
A5: Net operating profit | B5: ='Annual Views'!B15 -> 21334.155 | C5: ='Annual Views'!C15 -> 46352.552 | D5: ='Annual Views'!D15 -> 127357.01
A6: + Owner salary and payroll taxes | B6: =SUM('Monthly Model'!$B$59:$M$59) -> 0 | C6: =SUM('Monthly Model'!$N$59:$Y$59) -> 48000 | D6: =SUM('Monthly Model'!$Z$59:$AK$59) -> 96000
A7: + Owner benefits | B7: =0 -> 0 | C7: =0 -> 0 | D7: =0 -> 0
A8: + Interest, depreciation, amortisation | B8: =0 -> 0 | C8: =0 -> 0 | D8: =0 -> 0
A9: + One-time costs (legal, brand, trademark) | B9: =SUM('Monthly Model'!$B$64:$M$64) -> 3850 | C9: =SUM('Monthly Model'!$N$64:$Y$64) -> 0 | D9: =SUM('Monthly Model'!$Z$64:$AK$64) -> 0
A10: + Personal expenses through the business | B10: =0 -> 0 | C10: =0 -> 0 | D10: =0 -> 0
A11: − Replace second founder (unpaid hours) | B11: =-Assumptions!$B$48 -> -26000 | C11: =-Assumptions!$B$48 -> -26000 | D11: =-Assumptions!$B$48 -> -26000
A12: − Replace founder concierge review (pre-hire months) | B12: =-SUMIFS('Monthly Model'!$B$15:$M$15,'Monthly Model'!$B$4:$M$4,"<"&Assumptions!$B$42)*Assumptions!$B$40*Assumptions!$B$41 -> -4305 | C12: =-SUMIFS('Monthly Model'!$N$15:$Y$15,'Monthly Model'!$N$4:$Y$4,"<"&Assumptions!$B$42)*Assumptions!$B$40*Assumptions!$B$41 -> -1365 | D12: =-SUMIFS('Monthly Model'!$Z$15:$AK$15,'Monthly Model'!$Z$4:$AK$4,"<"&Assumptions!$B$42)*Assumptions!$B$40*Assumptions!$B$41 -> 0
A13: SDE | B13: =SUM(B5:B12) -> -5120.8448 | C13: =SUM(C5:C12) -> 66987.552 | D13: =SUM(D5:D12) -> 197357.01
A14: SDE margin | B14: =IF('Annual Views'!B5=0,0,B13/'Annual Views'!B5) -> -0.12763017 | C14: =IF('Annual Views'!C5=0,0,C13/'Annual Views'!C5) -> 0.3513216 | D14: =IF('Annual Views'!D5=0,0,D13/'Annual Views'!D5) -> 0.46184828
A16: Year-1 SDE is negative: the business earns operating profit, and still returns less than zero once two founders' unpaid time is priced at market. Year 1 is a funded experiment, not yet a business.

Sheet Monthly Model
A1: XPMatch — 36-Month Model
A2: Month 1 = October 2026, the month Stripe billing goes live. Blue = input. Black = formula. Change inputs here or scenario levers on Assumptions.
B3: M1 | C3: M2 | D3: M3 | E3: M4 | F3: M5 | G3: M6 | H3: M7 | I3: M8 | J3: M9 | K3: M10 | L3: M11 | M3: M12 | N3: M13 | O3: M14 | P3: M15 | Q3: M16 | R3: M17 | S3: M18 | T3: M19 | U3: M20 | V3: M21 | W3: M22 | X3: M23 | Y3: M24 | Z3: M25 | AA3: M26 | AB3: M27 | AC3: M28 | AD3: M29 | AE3: M30 | AF3: M31 | AG3: M32 | AH3: M33 | AI3: M34 | AJ3: M35 | AK3: M36
A4: Month # | B4: 1 | C4: =B4+1 -> 2 | D4: =C4+1 -> 3 | E4: =D4+1 -> 4 | F4: =E4+1 -> 5 | G4: =F4+1 -> 6 | H4: =G4+1 -> 7 | I4: =H4+1 -> 8 | J4: =I4+1 -> 9 | ... AK4: =AJ4+1 -> 36
A5: Year | B5: =IF(B4<=12,1,IF(B4<=24,2,3)) -> 1 | C5: =IF(C4<=12,1,IF(C4<=24,2,3)) -> 1 | D5: =IF(D4<=12,1,IF(D4<=24,2,3)) -> 1 | E5: =IF(E4<=12,1,IF(E4<=24,2,3)) -> 1 | F5: =IF(F4<=12,1,IF(F4<=24,2,3)) -> 1 | G5: =IF(G4<=12,1,IF(G4<=24,2,3)) -> 1 | H5: =IF(H4<=12,1,IF(H4<=24,2,3)) -> 1 | I5: =IF(I4<=12,1,IF(I4<=24,2,3)) -> 1 | ... AK5: =IF(AK4<=12,1,IF(AK4<=24,2,3)) -> 3
A7: § Volume inputs
A8: New free signups (base) | B8: 100 | C8: 150 | D8: 220 | E8: 300 | F8: 400 | G8: 500 | H8: 650 | I8: 800 | J8: 950 | K8: 1100 | L8: 1300 | M8: 1500 | N8: 1700 | O8: 1900 | P8: 2100 | Q8: 2300 | R8: 2500 | S8: 2700 | T8: 2900 | U8: 3100 | V8: 3300 | W8: 3500 | X8: 3700 | Y8: 3900 | Z8: 4100 | AA8: 4300 | AB8: 4500 | AC8: 4700 | AD8: 4900 | AE8: 5100 | AF8: 5300 | AG8: 5500 | AH8: 5700 | AI8: 5900 | AJ8: 6100 | AK8: 6300
A9: Advisor seat gross adds (base) | B9: 0 | C9: 0 | D9: 2 | E9: 3 | F9: 4 | G9: 5 | H9: 6 | I9: 6 | J9: 7 | K9: 8 | L9: 8 | M9: 9 | N9: 10 | O9: 11 | P9: 12 | Q9: 13 | R9: 14 | S9: 15 | T9: 16 | U9: 17 | V9: 18 | W9: 19 | X9: 20 | Y9: 21 | Z9: 22 | AA9: 23 | AB9: 24 | AC9: 25 | AD9: 26 | AE9: 27 | AF9: 28 | AG9: 29 | AH9: 30 | AI9: 31 | AJ9: 32 | AK9: 33
A10: Concierge trips (base) | B10: 2 | C10: 3 | D10: 4 | E10: 5 | F10: 6 | G10: 7 | H10: 8 | I10: 8 | J10: 9 | K10: 10 | L10: 10 | M10: 10 | N10: 12 | O10: 14 | P10: 16 | Q10: 18 | R10: 20 | S10: 20 | T10: 22 | U10: 22 | V10: 24 | W10: 24 | X10: 25 | Y10: 25 | Z10: 25 | AA10: 26 | AB10: 26 | AC10: 27 | AD10: 27 | AE10: 28 | AF10: 28 | AG10: 29 | AH10: 29 | AI10: 30 | AJ10: 30 | AK10: 30
A12: § Drivers (after scenario levers)
A13: Signups after lever | B13: =B8*Assumptions!$B$65 -> 100 | C13: =C8*Assumptions!$B$65 -> 150 | D13: =D8*Assumptions!$B$65 -> 220 | E13: =E8*Assumptions!$B$65 -> 300 | F13: =F8*Assumptions!$B$65 -> 400 | G13: =G8*Assumptions!$B$65 -> 500 | H13: =H8*Assumptions!$B$65 -> 650 | I13: =I8*Assumptions!$B$65 -> 800 | ... AK13: =AK8*Assumptions!$B$65 -> 6300
A14: Seat adds after lever | B14: =B9*Assumptions!$B$63 -> 0 | C14: =C9*Assumptions!$B$63 -> 0 | D14: =D9*Assumptions!$B$63 -> 2 | E14: =E9*Assumptions!$B$63 -> 3 | F14: =F9*Assumptions!$B$63 -> 4 | G14: =G9*Assumptions!$B$63 -> 5 | H14: =H9*Assumptions!$B$63 -> 6 | I14: =I9*Assumptions!$B$63 -> 6 | ... AK14: =AK9*Assumptions!$B$63 -> 33
A15: Concierge trips after lever | B15: =B10*Assumptions!$B$67 -> 2 | C15: =C10*Assumptions!$B$67 -> 3 | D15: =D10*Assumptions!$B$67 -> 4 | E15: =E10*Assumptions!$B$67 -> 5 | F15: =F10*Assumptions!$B$67 -> 6 | G15: =G10*Assumptions!$B$67 -> 7 | H15: =H10*Assumptions!$B$67 -> 8 | I15: =I10*Assumptions!$B$67 -> 8 | ... AK15: =AK10*Assumptions!$B$67 -> 30
A16: Free-to-paid conversion | B16: =INDEX(Assumptions!$B$56:$D$56,1,B5)*Assumptions!$B$64 -> 0.04 | C16: =INDEX(Assumptions!$B$56:$D$56,1,C5)*Assumptions!$B$64 -> 0.04 | D16: =INDEX(Assumptions!$B$56:$D$56,1,D5)*Assumptions!$B$64 -> 0.04 | E16: =INDEX(Assumptions!$B$56:$D$56,1,E5)*Assumptions!$B$64 -> 0.04 | F16: =INDEX(Assumptions!$B$56:$D$56,1,F5)*Assumptions!$B$64 -> 0.04 | G16: =INDEX(Assumptions!$B$56:$D$56,1,G5)*Assumptions!$B$64 -> 0.04 | H16: =INDEX(Assumptions!$B$56:$D$56,1,H5)*Assumptions!$B$64 -> 0.04 | I16: =INDEX(Assumptions!$B$56:$D$56,1,I5)*Assumptions!$B$64 -> 0.04 | ... AK16: =INDEX(Assumptions!$B$56:$D$56,1,AK5)*Assumptions!$B$64 -> 0.06
A17: Annual share of Plus | B17: =INDEX(Assumptions!$B$57:$D$57,1,B5) -> 0.5 | C17: =INDEX(Assumptions!$B$57:$D$57,1,C5) -> 0.5 | D17: =INDEX(Assumptions!$B$57:$D$57,1,D5) -> 0.5 | E17: =INDEX(Assumptions!$B$57:$D$57,1,E5) -> 0.5 | F17: =INDEX(Assumptions!$B$57:$D$57,1,F5) -> 0.5 | G17: =INDEX(Assumptions!$B$57:$D$57,1,G5) -> 0.5 | H17: =INDEX(Assumptions!$B$57:$D$57,1,H5) -> 0.5 | I17: =INDEX(Assumptions!$B$57:$D$57,1,I5) -> 0.5 | ... AK17: =INDEX(Assumptions!$B$57:$D$57,1,AK5) -> 0.65
A18: Affiliate revenue per trip | B18: =INDEX(Assumptions!$B$58:$D$58,1,B5)*Assumptions!$B$68 -> 1.5 | C18: =INDEX(Assumptions!$B$58:$D$58,1,C5)*Assumptions!$B$68 -> 1.5 | D18: =INDEX(Assumptions!$B$58:$D$58,1,D5)*Assumptions!$B$68 -> 1.5 | E18: =INDEX(Assumptions!$B$58:$D$58,1,E5)*Assumptions!$B$68 -> 1.5 | F18: =INDEX(Assumptions!$B$58:$D$58,1,F5)*Assumptions!$B$68 -> 1.5 | G18: =INDEX(Assumptions!$B$58:$D$58,1,G5)*Assumptions!$B$68 -> 1.5 | H18: =INDEX(Assumptions!$B$58:$D$58,1,H5)*Assumptions!$B$68 -> 1.5 | I18: =INDEX(Assumptions!$B$58:$D$58,1,I5)*Assumptions!$B$68 -> 1.5 | ... AK18: =INDEX(Assumptions!$B$58:$D$58,1,AK5)*Assumptions!$B$68 -> 4
A19: Advisor seat monthly churn | B19: =INDEX(Assumptions!$B$59:$D$59,1,B5) -> 0.05 | C19: =INDEX(Assumptions!$B$59:$D$59,1,C5) -> 0.05 | D19: =INDEX(Assumptions!$B$59:$D$59,1,D5) -> 0.05 | E19: =INDEX(Assumptions!$B$59:$D$59,1,E5) -> 0.05 | F19: =INDEX(Assumptions!$B$59:$D$59,1,F5) -> 0.05 | G19: =INDEX(Assumptions!$B$59:$D$59,1,G5) -> 0.05 | H19: =INDEX(Assumptions!$B$59:$D$59,1,H5) -> 0.05 | I19: =INDEX(Assumptions!$B$59:$D$59,1,I5) -> 0.05 | ... AK19: =INDEX(Assumptions!$B$59:$D$59,1,AK5) -> 0.03
A21: § Customer rollforward
A22: New paid conversions | B22: =B13*B16 -> 4 | C22: =C13*C16 -> 6 | D22: =D13*D16 -> 8.8 | E22: =E13*E16 -> 12 | F22: =F13*F16 -> 16 | G22: =G13*G16 -> 20 | H22: =H13*H16 -> 26 | I22: =I13*I16 -> 32 | ... AK22: =AK13*AK16 -> 378
A23: Trip Pass units | B23: =B22*Assumptions!$B$12 -> 2.2 | C23: =C22*Assumptions!$B$12 -> 3.3 | D23: =D22*Assumptions!$B$12 -> 4.84 | E23: =E22*Assumptions!$B$12 -> 6.6 | F23: =F22*Assumptions!$B$12 -> 8.8 | G23: =G22*Assumptions!$B$12 -> 11 | H23: =H22*Assumptions!$B$12 -> 14.3 | I23: =I22*Assumptions!$B$12 -> 17.6 | ... AK23: =AK22*Assumptions!$B$12 -> 207.9
A24: New Plus subscribers | B24: =B22-B23 -> 1.8 | C24: =C22-C23 -> 2.7 | D24: =D22-D23 -> 3.96 | E24: =E22-E23 -> 5.4 | F24: =F22-F23 -> 7.2 | G24: =G22-G23 -> 9 | H24: =H22-H23 -> 11.7 | I24: =I22-I23 -> 14.4 | ... AK24: =AK22-AK23 -> 170.1
A25: New Plus — annual | B25: =B24*B17 -> 0.9 | C25: =C24*C17 -> 1.35 | D25: =D24*D17 -> 1.98 | E25: =E24*E17 -> 2.7 | F25: =F24*F17 -> 3.6 | G25: =G24*G17 -> 4.5 | H25: =H24*H17 -> 5.85 | I25: =I24*I17 -> 7.2 | ... AK25: =AK24*AK17 -> 110.565
A26: New Plus — monthly | B26: =B24-B25 -> 0.9 | C26: =C24-C25 -> 1.35 | D26: =D24-D25 -> 1.98 | E26: =E24-E25 -> 2.7 | F26: =F24-F25 -> 3.6 | G26: =G24-G25 -> 4.5 | H26: =H24-H25 -> 5.85 | I26: =I24-I25 -> 7.2 | ... AK26: =AK24-AK25 -> 59.535
A27: Annual cohort started (new + renewals) | B27: =B25 -> 0.9 | C27: =C25 -> 1.35 | D27: =D25 -> 1.98 | E27: =E25 -> 2.7 | F27: =F25 -> 3.6 | G27: =G25 -> 4.5 | H27: =H25 -> 5.85 | I27: =I25 -> 7.2 | ... M27: =M25 -> 13.5 | N27: =N25+B27*Assumptions!$B$14 -> 23.355 | O27: =O25+C27*Assumptions!$B$14 -> 26.2575 | P27: =P25+D27*Assumptions!$B$14 -> 29.241 | Q27: =Q25+E27*Assumptions!$B$14 -> 32.265 | R27: =R25+F27*Assumptions!$B$14 -> 35.37 | S27: =S25+G27*Assumptions!$B$14 -> 38.475 | T27: =T25+H27*Assumptions!$B$14 -> 41.7825 | U27: =U25+I27*Assumptions!$B$14 -> 45.09 | ... AK27: =AK25+Y27*Assumptions!$B$14 -> 136.99125
A28: Plus subscribers — annual (active) | B28: =SUM(B27:B27) -> 0.9 | C28: =SUM(B27:C27) -> 2.25 | D28: =SUM(B27:D27) -> 4.23 | E28: =SUM(B27:E27) -> 6.93 | F28: =SUM(B27:F27) -> 10.53 | G28: =SUM(B27:G27) -> 15.03 | H28: =SUM(B27:H27) -> 20.88 | I28: =SUM(B27:I27) -> 28.08 | J28: =SUM(B27:J27) -> 36.63 | K28: =SUM(B27:K27) -> 46.53 | L28: =SUM(B27:L27) -> 58.23 | M28: =SUM(B27:M27) -> 71.73 | N28: =SUM(C27:N27) -> 94.185 | O28: =SUM(D27:O27) -> 119.0925 | P28: =SUM(E27:P27) -> 146.3535 | Q28: =SUM(F27:Q27) -> 175.9185 | R28: =SUM(G27:R27) -> 207.6885 | S28: =SUM(H27:S27) -> 241.6635 | T28: =SUM(I27:T27) -> 277.596 | ... AK28: =SUM(Z27:AK27) -> 1313.7653
A29: Plus subscribers — monthly (active) | B29: =B26 -> 0.9 | C29: =B29*(1-Assumptions!$B$13)+C26 -> 2.142 | D29: =C29*(1-Assumptions!$B$13)+D26 -> 3.86496 | E29: =D29*(1-Assumptions!$B$13)+E26 -> 6.1011648 | F29: =E29*(1-Assumptions!$B$13)+F26 -> 8.969025 | G29: =F29*(1-Assumptions!$B$13)+G26 -> 12.392742 | H29: =G29*(1-Assumptions!$B$13)+H26 -> 16.755613 | I29: =H29*(1-Assumptions!$B$13)+I26 -> 21.944939 | J29: =I29*(1-Assumptions!$B$13)+J26 -> 27.861547 | ... AK29: =AJ29*(1-Assumptions!$B$13)+AK26 -> 380.88732
A30: Advisor seats (active) | B30: =B14 -> 0 | C30: =B30*(1-C19)+C14 -> 0 | D30: =C30*(1-D19)+D14 -> 2 | E30: =D30*(1-E19)+E14 -> 4.9 | F30: =E30*(1-F19)+F14 -> 8.655 | G30: =F30*(1-G19)+G14 -> 13.22225 | H30: =G30*(1-H19)+H14 -> 18.561138 | I30: =H30*(1-I19)+I14 -> 23.633081 | J30: =I30*(1-J19)+J14 -> 29.451427 | ... AK30: =AJ30*(1-AK19)+AK14 -> 405.47699
A31: Free active users | B31: =B13 -> 100 | C31: =B31*(1-Assumptions!$B$15)+C13 -> 230 | D31: =C31*(1-Assumptions!$B$15)+D13 -> 404 | E31: =D31*(1-Assumptions!$B$15)+E13 -> 623.2 | F31: =E31*(1-Assumptions!$B$15)+F13 -> 898.56 | G31: =F31*(1-Assumptions!$B$15)+G13 -> 1218.848 | H31: =G31*(1-Assumptions!$B$15)+H13 -> 1625.0784 | I31: =H31*(1-Assumptions!$B$15)+I13 -> 2100.0627 | J31: =I31*(1-Assumptions!$B$15)+J13 -> 2630.0502 | ... AK31: =AJ31*(1-Assumptions!$B$15)+AK13 -> 27505.15
A32: Paying accounts | B32: =B28+B29+B30 -> 1.8 | C32: =C28+C29+C30 -> 4.392 | D32: =D28+D29+D30 -> 10.09496 | E32: =E28+E29+E30 -> 17.931165 | F32: =F28+F29+F30 -> 28.154025 | G32: =G28+G29+G30 -> 40.644992 | H32: =H28+H29+H30 -> 56.19675 | I32: =I28+I29+I30 -> 73.65802 | ... AK32: =AK28+AK29+AK30 -> 2100.1296
A33: Trips planned | B33: =B13*Assumptions!$B$51+B32*Assumptions!$B$52 -> 20.216 | C33: =C13*Assumptions!$B$51+C32*Assumptions!$B$52 -> 30.52704 | D33: =D13*Assumptions!$B$51+D32*Assumptions!$B$52 -> 45.211395 | E33: =E13*Assumptions!$B$51+E32*Assumptions!$B$52 -> 62.15174 | F33: =F13*Assumptions!$B$51+F32*Assumptions!$B$52 -> 83.378483 | G33: =G13*Assumptions!$B$51+G32*Assumptions!$B$52 -> 104.8774 | H33: =H13*Assumptions!$B$51+H32*Assumptions!$B$52 -> 136.74361 | I33: =I13*Assumptions!$B$51+I32*Assumptions!$B$52 -> 168.83896 | ... AK33: =AK13*Assumptions!$B$51+AK32*Assumptions!$B$52 -> 1512.0156
A35: § Revenue
A36: Plus — annual | B36: =B28*Assumptions!$B$6/12 -> 3.675 | C36: =C28*Assumptions!$B$6/12 -> 9.1875 | D36: =D28*Assumptions!$B$6/12 -> 17.2725 | E36: =E28*Assumptions!$B$6/12 -> 28.2975 | F36: =F28*Assumptions!$B$6/12 -> 42.9975 | G36: =G28*Assumptions!$B$6/12 -> 61.3725 | H36: =H28*Assumptions!$B$6/12 -> 85.26 | I36: =I28*Assumptions!$B$6/12 -> 114.66 | ... AK36: =AK28*Assumptions!$B$6/12 -> 5364.5417
A37: Plus — monthly | B37: =B29*Assumptions!$B$7 -> 7.191 | C37: =C29*Assumptions!$B$7 -> 17.11458 | D37: =D29*Assumptions!$B$7 -> 30.88103 | E37: =E29*Assumptions!$B$7 -> 48.748307 | F37: =F29*Assumptions!$B$7 -> 71.66251 | G37: =G29*Assumptions!$B$7 -> 99.018009 | H37: =H29*Assumptions!$B$7 -> 133.87735 | I37: =I29*Assumptions!$B$7 -> 175.34007 | ... AK37: =AK29*Assumptions!$B$7 -> 3043.2897
A38: Trip Pass | B38: =B23*Assumptions!$B$8 -> 41.8 | C38: =C23*Assumptions!$B$8 -> 62.7 | D38: =D23*Assumptions!$B$8 -> 91.96 | E38: =E23*Assumptions!$B$8 -> 125.4 | F38: =F23*Assumptions!$B$8 -> 167.2 | G38: =G23*Assumptions!$B$8 -> 209 | H38: =H23*Assumptions!$B$8 -> 271.7 | I38: =I23*Assumptions!$B$8 -> 334.4 | ... AK38: =AK23*Assumptions!$B$8 -> 3950.1
A39: Advisor seats | B39: =B30*Assumptions!$B$9 -> 0 | C39: =C30*Assumptions!$B$9 -> 0 | D39: =D30*Assumptions!$B$9 -> 98 | E39: =E30*Assumptions!$B$9 -> 240.1 | F39: =F30*Assumptions!$B$9 -> 424.095 | G39: =G30*Assumptions!$B$9 -> 647.89025 | H39: =H30*Assumptions!$B$9 -> 909.49574 | I39: =I30*Assumptions!$B$9 -> 1158.021 | ... AK39: =AK30*Assumptions!$B$9 -> 19868.372
A40: Concierge | B40: =B15*Assumptions!$B$10 -> 498 | C40: =C15*Assumptions!$B$10 -> 747 | D40: =D15*Assumptions!$B$10 -> 996 | E40: =E15*Assumptions!$B$10 -> 1245 | F40: =F15*Assumptions!$B$10 -> 1494 | G40: =G15*Assumptions!$B$10 -> 1743 | H40: =H15*Assumptions!$B$10 -> 1992 | I40: =I15*Assumptions!$B$10 -> 1992 | ... AK40: =AK15*Assumptions!$B$10 -> 7470
A41: Affiliate commissions | B41: =IF(B4>=6,B33*B18,0) -> 0 | C41: =IF(C4>=6,C33*C18,0) -> 0 | D41: =IF(D4>=6,D33*D18,0) -> 0 | E41: =IF(E4>=6,E33*E18,0) -> 0 | F41: =IF(F4>=6,F33*F18,0) -> 0 | G41: =IF(G4>=6,G33*G18,0) -> 157.3161 | H41: =IF(H4>=6,H33*H18,0) -> 205.11542 | I41: =IF(I4>=6,I33*I18,0) -> 253.25844 | ... AK41: =IF(AK4>=6,AK33*AK18,0) -> 6048.0622
A42: Total revenue | B42: =SUM(B36:B41) -> 550.666 | C42: =SUM(C36:C41) -> 836.00208 | D42: =SUM(D36:D41) -> 1234.1135 | E42: =SUM(E36:E41) -> 1687.5458 | F42: =SUM(F36:F41) -> 2199.955 | G42: =SUM(G36:G41) -> 2917.5969 | H42: =SUM(H36:H41) -> 3597.4485 | I42: =SUM(I36:I41) -> 4027.6795 | ... AK42: =SUM(AK36:AK41) -> 45744.366
A43: Cash collected (annual billed upfront) | B43: =B27*Assumptions!$B$6+B37+B38+B39+B40+B41 -> 591.091 | C43: =C27*Assumptions!$B$6+C37+C38+C39+C40+C41 -> 892.96458 | D43: =D27*Assumptions!$B$6+D37+D38+D39+D40+D41 -> 1313.861 | E43: =E27*Assumptions!$B$6+E37+E38+E39+E40+E41 -> 1791.5483 | F43: =F27*Assumptions!$B$6+F37+F38+F39+F40+F41 -> 2333.3575 | G43: =G27*Assumptions!$B$6+G37+G38+G39+G40+G41 -> 3076.7244 | H43: =H27*Assumptions!$B$6+H37+H38+H39+H40+H41 -> 3798.8385 | I43: =I27*Assumptions!$B$6+I37+I38+I39+I40+I41 -> 4265.8195 | ... AK43: =AK27*Assumptions!$B$6+AK37+AK38+AK39+AK40+AK41 -> 47092.395
A45: § Cost of goods sold
...

Sheet Assumptions
A1: XPMatch — Model Assumptions
A2: Blue = input you can change. Black = formula. Yellow = scenario lever. Every projection line traces to a row here.
A4: Assumption | B4: Value | C4: Tag | D4: Source | E4: Used in
A5: § Pricing
A6: Plus annual price | B6: 49 | C6: E | D6: Layla $49.99/yr, TripIt Pro $49/yr, Wanderlog Pro $39.99/yr (Sep 2026) | E6: Plus revenue
A7: Plus monthly price | B7: 7.99 | C7: E | D7: Priced below Layla $9.99/mo | E7: Plus revenue
A8: Trip Pass price (60 days) | B8: 19 | C8: A | D8: No direct comparable; StayMatch $10 day pass is nearest | E8: Trip Pass revenue
A9: Advisor seat price / month | B9: 49 | C9: E | D9: Travefy $39-59/mo; Tern $39/seat/mo | E9: Seat revenue
A10: Concierge average price | B10: 249 | C10: E | D10: AAA international planning fees $250-1,500 | E10: Concierge revenue
A11: § Retention & mix
A12: Trip Pass share of paid conversions | B12: 0.55 | C12: A | D12: Judgement: lower friction at Turn-into-a-trip | E12: Revenue mix
A13: Plus monthly churn | B13: 0.12 | C13: E | D13: RevenueCat 2026: travel monthly first renewal ~53% | E13: Plus rollforward
A14: Plus annual renewal at 12 months | B14: 0.45 | C14: E | D14: RevenueCat 2026: travel annual ~40%, +5pts for taste profile | E14: Plus rollforward
A15: Free base monthly decay | B15: 0.2 | C15: A | D15: No cohort data exists | E15: Active user count
A16: § Google list prices (per call)
A17: Place Details Enterprise | B17: 0.035 | C17: V | D17: Only for a place id never stored, plus the 30-day refresh | E17: Shared city cost
A18: Place Details + Atmosphere | B18: 0.04 | C18: V | D18: Place sheet / Ask; cached 30 days in place_facts, shared | E18: Shared city cost
A19: Text / Nearby Search Enterprise | B19: 0.035 | C19: V | D19: Returns up to 20 places for one fee; cached 24h, shared | E19: Shared city cost, seeding
A20: Place Photos | B20: 0.007 | C20: V | D20: Cached 24h in photo_urls, shared by everyone | E20: Shared city cost
A21: Dynamic Maps (per load) | B21: 0.007 | C21: V | D21: Client-side, per user, never shared | E21: Unshared per user
A22: Routes Essentials | B22: 0.005 | C22: V | D22: Per routed leg | E22: Unshared per user
A23: Model, per message | B23: 0.005 | C23: E | D23: OpenRouter, openai/gpt-4o-mini | E23: Unshared per user
A24: § Cost shape: per city, not per user
A25: Seed queries per city | B25: 20 | C25: V | D25: SEED_QUERIES in src/server/seed.ts | E25: Seeding cost
A26: Catalog places per city | B26: 380 | C26: E | D26: ~20 queries x ~20 results, deduped | E26: Saturation pool
A27: Distinct list-search queries per city | B27: 60 | C27: A | D27: Explore tabs + home picks | E27: Saturation pool
A28: Places shown / effective user / month | B28: 60 | C28: A | D28: UNMEASURED - /admin now reports the real number | E28: Shared city cost
A29: Photos shown / effective user / month | B29: 60 | C29: A | D29: UNMEASURED | E29: Shared city cost
A30: Place sheets / effective user / month | B30: 10 | C30: A | D30: UNMEASURED | E30: Shared city cost
A31: List searches / effective user / month | B31: 8 | C31: A | D31: UNMEASURED | E31: Shared city cost
A32: Messages / effective user / month | B32: 20 | C32: A | D32: UNMEASURED | E32: Unshared per user
A33: Map loads / effective user / month | B33: 10 | C33: A | D33: UNMEASURED | E33: Unshared per user
A34: Routed legs / effective user / month | B34: 6 | C34: A | D34: UNMEASURED | E34: Unshared per user
A35: Days active / month | B35: 6 | C35: A | D35: Drives the 24h photo and search TTLs. Engagement costs more than usage | E35: Shared city cost
A36: Free-user traffic weight | B36: 0.3 | C36: A | D36: Lookup traffic vs one paying consumer; free tier is capped at 40/day | E36: Effective users
... A42: Reviewer start month | B42: 15 | C42: A | D42: Plan hires above 20 trips/month | E42: Concierge COGS, SDE
A43: § Processing & capital
A44: Payment processing rate | B44: 0.029 | C44: V | D44: Stripe published US pricing | E44: Processing COGS
A45: Payment processing fixed / txn | B45: 0.3 | C45: V | D45: Stripe published US pricing | E45: Processing COGS
A46: Founder capital at month 1 | B46: 25000 | C46: A | D46: Default - not supplied by founder | E46: Cumulative cash
...
