Workbook

Sheet Start Here
A1: XPMatch — Seven Revenue Paths: Financial Model
A2: Companion to 4-revenue-path-validation.md · Built Sep 22, 2026
A4: HOW TO USE THIS
A5: 1. Drivers tab — set the SCENARIO cell to 1 (Conservative), 2 (Base) or 3 (Aggressive).
A6: Every path tab and the Portfolio recompute instantly.
A7: 2. Or edit any blue driver directly to model your own case.
A8: 3. Portfolio tab — switch paths ON (1) or OFF (0) and read the adjusted total.
A9: 4. Portfolio also checks whether you can actually STAFF the paths you switched on.
A11: WHY THE PORTFOLIO TOTAL IS LOWER THAN THE SUM
A12: Paths 2 and 3 monetise the SAME trips. Paths 1 and 5 sell into the SAME DMO budget line.
A13: Adding all seven counts one unit of demand two or three times. The Portfolio tab removes that.
A15: WHAT THE RESEARCH CHANGED (see 4-revenue-path-validation for sources)
... A27: Every figure in this workbook is a projection under stated assumptions. XPMatch has zero revenue today.

Sheet Drivers
A1: Revenue Path Drivers — all seven paths
A2: Blue = edit me. Yellow = the scenario switch. ACTIVE column feeds every path tab.
A4: SCENARIO (1 = Conservative, 2 = Base, 3 = Aggressive) | B4: 2 | C4: =INDEX({"Conservative","Base","Aggressive"},1,$B$4) -> Base
A6: Driver | B6: Conservative | C6: Base | D6: Aggressive | E6: ACTIVE | F6: Unit | G6: Note
A7: P1 · White-label DMO
A8: Clients at end of Y1 | B8: 1 | C8: 2 | D8: 4 | E8: =INDEX($B8:$D8,1,$B$4) -> 2 | F8: clients
A9: Clients at end of Y2 | B9: 3 | C9: 6 | D9: 10 | E9: =INDEX($B9:$D9,1,$B$4) -> 6 | F9: clients
A10: Clients at end of Y3 | B10: 6 | C10: 12 | D10: 20 | E10: =INDEX($B10:$D10,1,$B$4) -> 12 | F10: clients | G10: Your claim was 20 by Y3
A11: Price per client / month | B11: 2000 | C11: 3000 | D11: 5000 | E11: =INDEX($B11:$D11,1,$B$4) -> 3000 | F11: $/mo | G11: Your claim was $5,000
A12: Support + infra per client / month | B12: 250 | C12: 250 | D12: 250 | E12: =INDEX($B12:$D12,1,$B$4) -> 250 | F12: $/mo
A13: White-label build (one-time, Y1) | B13: 60000 | C13: 60000 | D13: 60000 | E13: =INDEX($B13:$D13,1,$B$4) -> 60000 | F13: $ | G13: 6-10 weeks eng; not in codebase
A14: Hours per client / year | B14: 120 | C14: 120 | D14: 120 | E14: =INDEX($B14:$D14,1,$B$4) -> 120 | F14: hrs | G14: Success + support
A15: Fixed sales hours / year | B15: 600 | C15: 600 | D15: 600 | E15: =INDEX($B15:$D15,1,$B$4) -> 600 | F15: hrs | G15: 6-18 month procurement cycles
A17: P2 · Revenue share
A18: Partners live in Y1 | B18: 0 | C18: 0 | D18: 0 | E18: =INDEX($B18:$D18,1,$B$4) -> 0 | F18: partners
A19: Partners live in Y2 | B19: 0 | C19: 1 | D19: 1 | E19: =INDEX($B19:$D19,1,$B$4) -> 1 | F19: partners
A20: Partners live in Y3 | B20: 1 | C20: 2 | D20: 3 | E20: =INDEX($B20:$D20,1,$B$4) -> 2 | F20: partners
A21: Attributed GMV per partner / year | B21: 1000000 | C21: 2000000 | D21: 5000000 | E21: =INDEX($B21:$D21,1,$B$4) -> 2000000 | F21: $ | G21: Your claim was $10M total
A22: Incrementality accepted | B22: 0.2 | C22: 0.3 | D22: 0.5 | E22: =INDEX($B22:$D22,1,$B$4) -> 0.3 | F22: % | G22: Holdout tests cut this hard
A23: Take rate on incremental | B23: 0.1 | C23: 0.1 | D23: 0.125 | E23: =INDEX($B23:$D23,1,$B$4) -> 0.1 | F23: %
A24: Attribution infrastructure / year | B24: 20000 | C24: 20000 | D24: 25000 | E24: =INDEX($B24:$D24,1,$B$4) -> 20000 | F24: $
A25: Hours per partner / year | B25: 300 | C25: 300 | D25: 300 | E25: =INDEX($B25:$D25,1,$B$4) -> 300 | F25: hrs
A27: P3 · Booking commissions
A28: Trips planned Y1 | B28: 1685 | C28: 1685 | D28: 1685 | E28: =INDEX($B28:$D28,1,$B$4) -> 1685 | F28: trips | G28: From 2-financial-model.xlsx
A29: Trips planned Y2 | B29: 7448 | C29: 7448 | D29: 7448 | E29: =INDEX($B29:$D29,1,$B$4) -> 7448 | F29: trips | G29: From 2-financial-model.xlsx
A30: Trips planned Y3 | B30: 14644 | C30: 14644 | D30: 14644 | E30: =INDEX($B30:$D30,1,$B$4) -> 14644 | F30: trips | G30: From 2-financial-model.xlsx
A31: Booking attach rate | B31: 0.15 | C31: 0.25 | D31: 0.4 | E31: =INDEX($B31:$D31,1,$B$4) -> 0.25 | F31: % | G31: Share of planned trips that book
A32: Average basket (stay + 2 activities) | B32: 940 | C32: 940 | D32: 940 | E32: =INDEX($B32:$D32,1,$B$4) -> 940 | F32: $ | G32: $700 stay + $240 activities
A33: Blended commission rate | B33: 0.05 | C33: 0.055 | D33: 0.065 | E33: =INDEX($B33:$D33,1,$B$4) -> 0.055 | F33: % | G33: VERIFIED 5.0-6.5%. Your claim: 8%
A34: Integration build (one-time, Y1) | B34: 2000 | C34: 2000 | D34: 2000 | E34: =INDEX($B34:$D34,1,$B$4) -> 2000 | F34: $
A35: Fixed hours / year | B35: 80 | C35: 80 | D35: 80 | E35: =INDEX($B35:$D35,1,$B$4) -> 80 | F35: hrs
A37: P4 · Group / corporate
A38: Group trips Y1 | B38: 8 | C38: 12 | D38: 20 | E38: =INDEX($B38:$D38,1,$B$4) -> 12 | F38: trips
A39: Group trips Y2 | B39: 20 | C39: 30 | D39: 50 | E39: =INDEX($B39:$D39,1,$B$4) -> 30 | F39: trips
A40: Group trips Y3 | B40: 30 | C40: 45 | D40: 80 | E40: =INDEX($B40:$D40,1,$B$4) -> 45 | F40: trips | G40: Your claim was 100
A41: Net planning fee per trip | B41: 3000 | C41: 4500 | D41: 7500 | E41: =INDEX($B41:$D41,1,$B$4) -> 4500 | F41: $ | G41: Your claim was $7,500
A42: Delivery cost per trip | B42: 1400 | C42: 1200 | D42: 1000 | E42: =INDEX($B42:$D42,1,$B$4) -> 1200 | F42: $ | G42: Contractor planner time
A43: Sales cost as % of revenue | B43: 0.12 | C43: 0.1 | D43: 0.08 | E43: =INDEX($B43:$D43,1,$B$4) -> 0.1 | F43: %
A44: Delivery hours per trip | B44: 22 | C44: 22 | D44: 22 | E44: =INDEX($B44:$D44,1,$B$4) -> 22 | F44: hrs | G44: THE constraint on this path
A45: Fixed sales hours / year | B45: 300 | C45: 300 | D45: 300 | E45: =INDEX($B45:$D45,1,$B$4) -> 300 | F45: hrs
...

Sheet Portfolio
A1: Portfolio Roll-up
A2: Toggle a path ON (1) or OFF (0). The overlap haircuts stop the same demand being counted twice.
A4: Available founder+contractor FTE | B4: 1.25 | C4: Two founders at ~50 h/wk combined = 1.25 FTE
A5: P2/P3 overlap haircut (same bookings) | B5: 1 | C5: P2 and P3 monetise the SAME trips. 100% removes the double count.
A6: P1/P5 overlap haircut (same DMO budget) | B6: 0.4 | C6: Both sell to one DMO budget line.
A8: Path | B8: ON/OFF | C8: Y1 revenue | D8: Y2 revenue | E8: Y3 revenue | F8: Y3 gross profit | G8: Y3 margin | H8: Y3 FTE
A9: P1 · White-label DMO | B9: 1 | C9: ='P1 DMO'!B10*$B9 -> 36000 | D9: ='P1 DMO'!C10*$B9 -> 144000 | E9: ='P1 DMO'!D10*$B9 -> 324000 | F9: ='P1 DMO'!D15*$B9 -> 297000 | G9: =IF(E9=0,0,F9/E9) -> 0.91666667 | H9: ='P1 DMO'!D19*$B9 -> 1.1333333
A10: P2 · Revenue share | B10: 1 | C10: ='P2 RevShare'!B11*$B10 -> 0 | D10: ='P2 RevShare'!C11*$B10 -> 60000 | E10: ='P2 RevShare'!D11*$B10 -> 120000 | F10: ='P2 RevShare'!D15*$B10 -> 100000 | G10: =IF(E10=0,0,F10/E10) -> 0.83333333 | H10: ='P2 RevShare'!D19*$B10 -> 0.33333333
A11: P3 · Booking commissions | B11: 1 | C11: ='P3 Bookings'!B11*$B11 -> 21778.625 | D11: ='P3 Bookings'!C11*$B11 -> 96265.4 | E11: ='P3 Bookings'!D11*$B11 -> 189273.7 | F11: ='P3 Bookings'!D15*$B11 -> 189273.7 | G11: =IF(E11=0,0,F11/E11) -> 1 | H11: ='P3 Bookings'!D19*$B11 -> 0.044444444
A12: P4 · Group / corporate | B12: 1 | C12: ='P4 Group'!B9*$B12 -> 54000 | D12: ='P4 Group'!C9*$B12 -> 135000 | E12: ='P4 Group'!D9*$B12 -> 202500 | F12: ='P4 Group'!D14*$B12 -> 128250 | G12: =IF(E12=0,0,F12/E12) -> 0.63333333 | H12: ='P4 Group'!D18*$B12 -> 0.71666667
A13: P5 · Data / analytics | B13: 1 | C13: ='P5 Data'!B10*$B13 -> 0 | D13: ='P5 Data'!C10*$B13 -> 18000 | E13: ='P5 Data'!D10*$B13 -> 90000 | F13: ='P5 Data'!D14*$B13 -> 75000 | G13: =IF(E13=0,0,F13/E13) -> 0.83333333 | H13: ='P5 Data'!D18*$B13 -> 0.55555556
A14: P6 · Creator campaigns | B14: 1 | C14: ='P6 Creator'!B9*$B14 -> 24000 | D14: ='P6 Creator'!C9*$B14 -> 48000 | E14: ='P6 Creator'!D9*$B14 -> 72000 | F14: ='P6 Creator'!D13*$B14 -> 43200 | G14: =IF(E14=0,0,F14/E14) -> 0.6 | H14: ='P6 Creator'!D17*$B14 -> 0.33333333
A15: P7 · Premium membership | B15: 1 | C15: ='P7 Membership'!B10*$B15 -> 33000 | D15: ='P7 Membership'!C10*$B15 -> 129250 | E15: ='P7 Membership'!D10*$B15 -> 261250 | F15: ='P7 Membership'!D14*$B15 -> 147250 | G15: =IF(E15=0,0,F15/E15) -> 0.56363636 | H15: ='P7 Membership'!D18*$B15 -> 0.22222222
A16: Gross total (before overlap) | C16: =SUM(C9:C15) -> 168778.62 | D16: =SUM(D9:D15) -> 630515.4 | E16: =SUM(E9:E15) -> 1259023.7 | F16: =SUM(F9:F15) -> 979973.7 | G16: =IF(E16=0,0,F16/E16) -> 0.77836001 | H16: =SUM(H9:H15) -> 3.3388889
A18: Less: P2/P3 double count | C18: =-IF(AND($B$10=1,$B$11=1),MIN('P2 RevShare'!B11,'P3 Bookings'!B11)*$B$5,0) -> 0 | D18: =-IF(AND($B$10=1,$B$11=1),MIN('P2 RevShare'!C11,'P3 Bookings'!C11)*$B$5,0) -> -60000 | E18: =-IF(AND($B$10=1,$B$11=1),MIN('P2 RevShare'!D11,'P3 Bookings'!D11)*$B$5,0) -> -120000
A19: Less: P1/P5 same-budget overlap | C19: =-IF(AND($B$9=1,$B$13=1),'P5 Data'!B10*$B$6,0) -> 0 | D19: =-IF(AND($B$9=1,$B$13=1),'P5 Data'!C10*$B$6,0) -> -7200 | E19: =-IF(AND($B$9=1,$B$13=1),'P5 Data'!D10*$B$6,0) -> -36000
A20: ADJUSTED REVENUE — each unit of demand counted once | C20: =C16+C18+C19 -> 168778.62 | D20: =D16+D18+D19 -> 563315.4 | E20: =E16+E18+E19 -> 1103023.7
A22: § Feasibility check
A23: Year-3 FTE required by the paths switched on | C23: =H16 -> 3.3388889
A24: FTE available | C24: =$B$4 -> 1.25
A25: Gap (negative = you cannot staff this) | C25: =C24-C23 -> -2.0888889
A26: Verdict | C26: =IF(C25>=0,"STAFFABLE","NOT STAFFABLE - turn paths off or hire") -> NOT STAFFABLE - turn paths off or hire
A28: § Against your original claim
A29: Your stated total (all seven) | C29: 8150000
A30: This model, Year 3 adjusted | C30: =E20 -> 1103023.7
A31: Ratio | C31: =IF(C30=0,0,C29/C30) -> 7.3887805

Sheet P1 DMO
A1: P1 · White-label enterprise concierge (DMOs)
A2: Binding constraint: Reaching ~20 of the ~240 DMOs with the budget. GuideGeek, with a media brand behind it, reached 30.
B4: Year 1 | C4: Year 2 | D4: Year 3
A5: Volume
A6: Clients at year end | B6: =Drivers!$E$8 -> 2 | C6: =Drivers!$E$9 -> 6 | D6: =Drivers!$E$10 -> 12
A7: Average clients in year | B7: =(0+B6)/2 -> 1 | C7: =(B6+C6)/2 -> 4 | D7: =(C6+D6)/2 -> 9
A9: Revenue
A10: Subscription revenue | B10: =B7*Drivers!$E$11*12 -> 36000 | C10: =C7*Drivers!$E$11*12 -> 144000 | D10: =D7*Drivers!$E$11*12 -> 324000
A12: Costs
A13: Support + infrastructure | B13: =-B7*Drivers!$E$12*12 -> -3000 | C13: =-C7*Drivers!$E$12*12 -> -12000 | D13: =-D7*Drivers!$E$12*12 -> -27000
A14: White-label build (one-time) | B14: =-Drivers!$E$13 -> -60000 | C14: =0 -> 0 | D14: =0 -> 0
A15: Gross profit | B15: =B10+B13+B14 -> -27000 | C15: =C10+C13+C14 -> 132000 | D15: =D10+D13+D14 -> 297000
A16: Gross margin | B16: =IF(B10=0,0,B15/B10) -> -0.75 | C16: =IF(C10=0,0,C15/C10) -> 0.91666667 | D16: =IF(D10=0,0,D15/D10) -> 0.91666667
A18: Effort
A19: FTE required | B19: =(B6*Drivers!$E$14+Drivers!$E$15)/1800 -> 0.46666667 | C19: =(C6*Drivers!$E$14+Drivers!$E$15)/1800 -> 0.73333333 | D19: =(D6*Drivers!$E$14+Drivers!$E$15)/1800 -> 1.1333333

Sheet P2 RevShare
A1: P2 · Revenue share on attributed incremental bookings
A2: Binding constraint: Getting a sophisticated partner to accept that a booking was incremental. Holdout tests cut the payable base.
B4: Year 1 | C4: Year 2 | D4: Year 3
A5: Volume
A6: Partners live | B6: =Drivers!$E$18 -> 0 | C6: =Drivers!$E$19 -> 1 | D6: =Drivers!$E$20 -> 2
A7: Attributed GMV | B7: =B6*Drivers!$E$21 -> 0 | C7: =C6*Drivers!$E$21 -> 2000000 | D7: =D6*Drivers!$E$21 -> 4000000
A8: Incremental GMV accepted | B8: =B7*Drivers!$E$22 -> 0 | C8: =C7*Drivers!$E$22 -> 600000 | D8: =D7*Drivers!$E$22 -> 1200000
A10: Revenue
A11: Revenue share earned | B11: =B8*Drivers!$E$23 -> 0 | C11: =C8*Drivers!$E$23 -> 60000 | D11: =D8*Drivers!$E$23 -> 120000
A13: Costs
A14: Attribution infrastructure | B14: =IF(B6>0,-Drivers!$E$24,0) -> 0 | C14: =IF(C6>0,-Drivers!$E$24,0) -> -20000 | D14: =IF(D6>0,-Drivers!$E$24,0) -> -20000
A15: Gross profit | B15: =B11+B14 -> 0 | C15: =C11+C14 -> 40000 | D15: =D11+D14 -> 100000
A16: Gross margin | B16: =IF(B11=0,0,B15/B11) -> 0 | C16: =IF(C11=0,0,C15/C11) -> 0.66666667 | D16: =IF(D11=0,0,D15/D11) -> 0.83333333
A18: Effort
A19: FTE required | B19: =B6*Drivers!$E$25/1800 -> 0 | C19: =C6*Drivers!$E$25/1800 -> 0.16666667 | D19: =D6*Drivers!$E$25/1800 -> 0.33333333

Sheet P3 Bookings
A1: P3 · Booking marketplace commissions
A2: Binding constraint: Booked trip volume. The rate is verified at 5.0-6.5% blended, not 8% - stays pay least and are most of the basket.
B4: Year 1 | C4: Year 2 | D4: Year 3
A5: Volume
A6: Trips planned (from core model) | B6: =Drivers!$E$28 -> 1685 | C6: =Drivers!$E$29 -> 7448 | D6: =Drivers!$E$30 -> 14644
A7: Booked trips | B7: =B6*Drivers!$E$31 -> 421.25 | C7: =C6*Drivers!$E$31 -> 1862 | D7: =D6*Drivers!$E$31 -> 3661
A8: Gross booking value | B8: =B7*Drivers!$E$32 -> 395975 | C8: =C7*Drivers!$E$32 -> 1750280 | D8: =D7*Drivers!$E$32 -> 3441340
A10: Revenue
A11: Commission revenue | B11: =B8*Drivers!$E$33 -> 21778.625 | C11: =C8*Drivers!$E$33 -> 96265.4 | D11: =D8*Drivers!$E$33 -> 189273.7
A13: Costs
A14: Integration build (one-time) | B14: =-Drivers!$E$34 -> -2000 | C14: =0 -> 0 | D14: =0 -> 0
A15: Gross profit | B15: =B11+B14 -> 19778.625 | C15: =C11+C14 -> 96265.4 | D15: =D11+D14 -> 189273.7
A16: Gross margin | B16: =IF(B11=0,0,B15/B11) -> 0.90816684 | C16: =IF(C11=0,0,C15/C11) -> 1 | D16: =IF(D11=0,0,D15/D11) -> 1
A18: Effort
A19: FTE required | B19: =Drivers!$E$35/1800 -> 0.044444444 | C19: =Drivers!$E$35/1800 -> 0.044444444 | D19: =Drivers!$E$35/1800 -> 0.044444444

Sheet P4 Group
A1: P4 · Corporate / group planning
A2: Binding constraint: Founder and planner hours. This is a services P&L, not SaaS - revenue scales with people.
B4: Year 1 | C4: Year 2 | D4: Year 3
A5: Volume
A6: Group trips delivered | B6: =Drivers!$E$38 -> 12 | C6: =Drivers!$E$39 -> 30 | D6: =Drivers!$E$40 -> 45
A8: Revenue
A9: Planning fee revenue | B9: =B6*Drivers!$E$41 -> 54000 | C9: =C6*Drivers!$E$41 -> 135000 | D9: =D6*Drivers!$E$41 -> 202500
A11: Costs
A12: Delivery cost | B12: =-B6*Drivers!$E$42 -> -14400 | C12: =-C6*Drivers!$E$42 -> -36000 | D12: =-D6*Drivers!$E$42 -> -54000
A13: Sales cost | B13: =-B9*Drivers!$E$43 -> -5400 | C13: =-C9*Drivers!$E$43 -> -13500 | D13: =-D9*Drivers!$E$43 -> -20250
A14: Gross profit | B14: =B9+B12+B13 -> 34200 | C14: =C9+C12+C13 -> 85500 | D14: =D9+D12+D13 -> 128250
A15: Gross margin | B15: =IF(B9=0,0,B14/B9) -> 0.63333333 | C15: =IF(C9=0,0,C14/C9) -> 0.63333333 | D15: =IF(D9=0,0,D14/D9) -> 0.63333333
A17: Effort
A18: FTE required | B18: =(B6*Drivers!$E$44+Drivers!$E$45)/1800 -> 0.31333333 | C18: =(C6*Drivers!$E$44+Drivers!$E$45)/1800 -> 0.53333333 | D18: =(D6*Drivers!$E$44+Drivers!$E$45)/1800 -> 0.71666667

Sheet P5 Data
A1: P5 · Data and analytics SaaS
A2: Binding constraint: Data supply, not demand - and it sells into the same DMO budget line as P1.
B4: Year 1 | C4: Year 2 | D4: Year 3
A5: Volume
A6: Clients at year end | B6: =Drivers!$E$48 -> 0 | C6: =Drivers!$E$49 -> 2 | D6: =Drivers!$E$50 -> 8
A7: Average clients in year | B7: =(0+B6)/2 -> 0 | C7: =(B6+C6)/2 -> 1 | D7: =(C6+D6)/2 -> 5
A9: Revenue
A10: Subscription revenue | B10: =B7*Drivers!$E$51*12 -> 0 | C10: =C7*Drivers!$E$51*12 -> 18000 | D10: =D7*Drivers!$E$51*12 -> 90000
A12: Costs
A13: Data pipeline | B13: =0 -> 0 | C13: =-Drivers!$E$52 -> -15000 | D13: =-Drivers!$E$52 -> -15000
A14: Gross profit | B14: =B10+B13 -> 0 | C14: =C10+C13 -> 3000 | D14: =D10+D13 -> 75000
A15: Gross margin | B15: =IF(B10=0,0,B14/B10) -> 0 | C15: =IF(C10=0,0,C14/C10) -> 0.16666667 | D15: =IF(D10=0,0,D14/D10) -> 0.83333333
A17: Effort
A18: FTE required | B18: =(B6*Drivers!$E$53+Drivers!$E$54)/1800 -> 0.11111111 | C18: =(C6*Drivers!$E$53+Drivers!$E$54)/1800 -> 0.22222222 | D18: =(D6*Drivers!$E$53+Drivers!$E$54)/1800 -> 0.55555556

Sheet P6 Creator
A1: P6 · Managed creator campaigns
A2: Binding constraint: Fee basis. The industry charges 10-25% OF CAMPAIGN BUDGET, so a $15k campaign nets about $3k, not $15k.
B4: Year 1 | C4: Year 2 | D4: Year 3
A5: Volume
A6: Campaigns run | B6: =Drivers!$E$57 -> 8 | C6: =Drivers!$E$58 -> 16 | D6: =Drivers!$E$59 -> 24
A8: Revenue
A9: Net fee revenue | B9: =B6*Drivers!$E$60 -> 24000 | C9: =C6*Drivers!$E$60 -> 48000 | D9: =D6*Drivers!$E$60 -> 72000
A11: Costs
A12: Delivery cost | B12: =-B9*Drivers!$E$61 -> -9600 | C12: =-C9*Drivers!$E$61 -> -19200 | D12: =-D9*Drivers!$E$61 -> -28800
A13: Gross profit | B13: =B9+B12 -> 14400 | C13: =C9+C12 -> 28800 | D13: =D9+D12 -> 43200
A14: Gross margin | B14: =IF(B9=0,0,B13/B9) -> 0.6 | C14: =IF(C9=0,0,C13/C9) -> 0.6 | D14: =IF(D9=0,0,D13/D9) -> 0.6
A16: Effort
A17: FTE required | B17: =B6*Drivers!$E$62/1800 -> 0.11111111 | C17: =C6*Drivers!$E$62/1800 -> 0.22222222 | D17: =D6*Drivers!$E$62/1800 -> 0.33333333

Sheet P7 Membership
A1: P7 · Premium consumer membership
A2: Binding constraint: Price. Verified category cap is about $50/year (Wanderlog Pro $39.99, TripIt Pro $49). $180/year is 3.6x that.
B4: Year 1 | C4: Year 2 | D4: Year 3
A5: Volume
A6: Paying members at year end | B6: =Drivers!$E$65 -> 1200 | C6: =Drivers!$E$66 -> 3500 | D6: =Drivers!$E$67 -> 6000
A7: Average members in year | B7: =(0+B6)/2 -> 600 | C7: =(B6+C6)/2 -> 2350 | D7: =(C6+D6)/2 -> 4750
A9: Revenue
A10: Membership revenue | B10: =B7*Drivers!$E$68 -> 33000 | C10: =C7*Drivers!$E$68 -> 129250 | D10: =D7*Drivers!$E$68 -> 261250
A12: Costs
A13: COGS (API, model, hosting) | B13: =-B7*Drivers!$E$69 -> -14400 | C13: =-C7*Drivers!$E$69 -> -56400 | D13: =-D7*Drivers!$E$69 -> -114000
A14: Gross profit | B14: =B10+B13 -> 18600 | C14: =C10+C13 -> 72850 | D14: =D10+D13 -> 147250
A15: Gross margin | B15: =IF(B10=0,0,B14/B10) -> 0.56363636 | C15: =IF(C10=0,0,C14/C10) -> 0.56363636 | D15: =IF(D10=0,0,D14/D10) -> 0.56363636
A17: Effort
A18: FTE required | B18: =Drivers!$E$70/1800 -> 0.22222222 | C18: =Drivers!$E$70/1800 -> 0.22222222 | D18: =Drivers!$E$70/1800 -> 0.22222222
